Workbook

Sheet Cycling usage estimation
C2: Model selection
C4: Automatic model selection
C7: Month | F7: Weather data | I7: Average usage (weekday) | L7: Average usage (weekend)
C9: October | F9: Calgary weather (2015) | I9: 56 | L9: 40
C32: =IF(analysis!$L$43=TRUE,analysis!H63,"") -> Month | D32: =IF(analysis!$L$43=TRUE,analysis!I63,"") -> January | E32: =IF(analysis!$L$43=TRUE,analysis!J63,"") -> February | F32: =IF(analysis!$L$43=TRUE,analysis!K63,"") -> March | G32: =IF(analysis!$L$43=TRUE,analysis!L63,"") -> April | H32: =IF(analysis!$L$43=TRUE,analysis!M63,"") -> May | I32: =IF(analysis!$L$43=TRUE,analysis!N63,"") -> June | J32: =IF(analysis!$L$43=TRUE,analysis!O63,"") -> July | ... O32: =IF(analysis!$L$43=TRUE,analysis!T63,"") -> December
C33: =IF(analysis!$L$43=TRUE,analysis!H64,"") -> Usage (cyclists) | D33: =IF(analysis!$L$43=TRUE,analysis!I64,"") -> 37 | E33: =IF(analysis!$L$43=TRUE,analysis!J64,"") -> 34 | F33: =IF(analysis!$L$43=TRUE,analysis!K64,"") -> 70 | G33: =IF(analysis!$L$43=TRUE,analysis!L64,"") -> 70 | H33: =IF(analysis!$L$43=TRUE,analysis!M64,"") -> 98 | I33: =IF(analysis!$L$43=TRUE,analysis!N64,"") -> 141 | J33: =IF(analysis!$L$43=TRUE,analysis!O64,"") -> 172 | ... O33: =IF(analysis!$L$43=TRUE,analysis!T64,"") -> 42
C35: Weekday usage | D35: =IF(analysis!$L$43=TRUE,analysis!I70,"") -> 22 | E35: =IF(analysis!$L$43=TRUE,analysis!J70,"") -> 20 | F35: =IF(analysis!$L$43=TRUE,analysis!K70,"") -> 41 | G35: =IF(analysis!$L$43=TRUE,analysis!L70,"") -> 41 | H35: =IF(analysis!$L$43=TRUE,analysis!M70,"") -> 57 | I35: =IF(analysis!$L$43=TRUE,analysis!N70,"") -> 82 | J35: =IF(analysis!$L$43=TRUE,analysis!O70,"") -> 100 | K35: =IF(analysis!$L$43=TRUE,analysis!P70,"") -> 85 | ... O35: =IF(analysis!$L$43=TRUE,analysis!T70,"") -> 25
C36: Weekend usage | D36: =IF(analysis!$L$43=TRUE,analysis!I71,"") -> 15 | E36: =IF(analysis!$L$43=TRUE,analysis!J71,"") -> 14 | F36: =IF(analysis!$L$43=TRUE,analysis!K71,"") -> 29 | G36: =IF(analysis!$L$43=TRUE,analysis!L71,"") -> 29 | H36: =IF(analysis!$L$43=TRUE,analysis!M71,"") -> 41 | I36: =IF(analysis!$L$43=TRUE,analysis!N71,"") -> 59 | J36: =IF(analysis!$L$43=TRUE,analysis!O71,"") -> 72 | K36: =IF(analysis!$L$43=TRUE,analysis!P71,"") -> 61 | ... O36: =IF(analysis!$L$43=TRUE,analysis!T71,"") -> 18
C39: weekend usage | E39: Estimated with | F39: =IF(D33 ="","","Utilitrian model") -> Utilitrian model | I39: Enter your weather data here
C41: weekday usage | E41: Estimated with | F41: =IF(D33="","",IF(C4="Commuter model","Commuter model",IF(C4="Utilitrian model","Utilitrian model",IF(C4="Automatic model selection",IF(L9/(L9+I9)>0.11,"Utilitrian model","Commuter model"))))) -> Utilitrian model
I42: Month | J42: Mean Temp (°C) | K42: Precipitation (mm) | L42: Snow on Grnd (cm) | M42: Wind speed (km/h) | N42: sunlight hours (h)
I43: January
I44: February
I45: March
I46: April
I47: May
I48: June
I49: July
I50: August
I51: September
I52: October
I53: November
I54: December

Sheet analysis
B1: month | C1: year | D1: weekdays usage | E1: weekend usage | F1: URT | H1: Automatic model selection | I1: Utilitrian model | J1: Commuter model
B2: ='Cycling usage estimation'!C9 -> October | C2: ='Cycling usage estimation'!F9 -> Calgary weather (2015) | D2: ='Cycling usage estimation'!I9 -> 56 | E2: ='Cycling usage estimation'!L9 -> 40 | F2: =E2/(D2+E2+1E-70) -> 0.41666667 | H2: selected model | J2: ='Cycling usage estimation'!C4 -> Automatic model selection
B4: weekeday commuter model | E4: weekday utilitria model | H4: weekend utilitrian model
B5: january | C5: =LOG($D$2)-(weather!B20*Models!D5)-(weather!C20*Models!E5)-(weather!D20*Models!F5)-(weather!E20*Models!G5)-(weather!F20*Models!H5) -> 2.416088 | E5: january | F5: =LOG($D$2)-(Models!D26*weather!B20)-(Models!E26*weather!C20)-(Models!F26*weather!D20)-(Models!G26*weather!E20)-(Models!H26*weather!F20) -> 2.197328 | H5: january | I5: =LOG(analysis!$E$2)-(Models!D26*weather!B20)-(Models!E26*weather!C20)-(Models!F26*weather!D20)-(Models!G26*weather!E20)-(Models!H26*weather!F20) -> 2.0512
B6: february | C6: =LOG($D$2)-(weather!B21*Models!D6)-(weather!C21*Models!E6)-(weather!D21*Models!F6)-(weather!E21*Models!G6)-(weather!F21*Models!H6) -> 2.004688 | E6: february | F6: =LOG($D$2)-(Models!D27*weather!B21)-(Models!E27*weather!C21)-(Models!F27*weather!D21)-(Models!G27*weather!E21)-(Models!H27*weather!F21) -> 2.232478 | H6: february | I6: =LOG(analysis!$E$2)-(Models!D27*weather!B21)-(Models!E27*weather!C21)-(Models!F27*weather!D21)-(Models!G27*weather!E21)-(Models!H27*weather!F21) -> 2.08635
B7: march | C7: =LOG($D$2)-(weather!B22*Models!D7)-(weather!C22*Models!E7)-(weather!D22*Models!F7)-(weather!E22*Models!G7)-(weather!F22*Models!H7) -> 1.836108 | E7: march | F7: =LOG($D$2)-(Models!D28*weather!B22)-(Models!E28*weather!C22)-(Models!F28*weather!D22)-(Models!G28*weather!E22)-(Models!H28*weather!F22) -> 1.921348 | H7: march | I7: =LOG(analysis!$E$2)-(Models!D28*weather!B22)-(Models!E28*weather!C22)-(Models!F28*weather!D22)-(Models!G28*weather!E22)-(Models!H28*weather!F22) -> 1.77522
B8: april | C8: =LOG($D$2)-(weather!B23*Models!D8)-(weather!C23*Models!E8)-(weather!D23*Models!F8)-(weather!E23*Models!G8)-(weather!F23*Models!H8) -> 1.850888 | E8: april | F8: =LOG($D$2)-(Models!D29*weather!B23)-(Models!E29*weather!C23)-(Models!F29*weather!D23)-(Models!G29*weather!E23)-(Models!H29*weather!F23) -> 1.921808 | H8: april | I8: =LOG(analysis!$E$2)-(Models!D29*weather!B23)-(Models!E29*weather!C23)-(Models!F29*weather!D23)-(Models!G29*weather!E23)-(Models!H29*weather!F23) -> 1.77568
B9: may | C9: =LOG($D$2)-(weather!B24*Models!D9)-(weather!C24*Models!E9)-(weather!D24*Models!F9)-(weather!E24*Models!G9)-(weather!F24*Models!H9) -> 1.740618 | E9: may | F9: =LOG($D$2)-(Models!D30*weather!B24)-(Models!E30*weather!C24)-(Models!F30*weather!D24)-(Models!G30*weather!E24)-(Models!H30*weather!F24) -> 1.773258 | H9: may | I9: =LOG(analysis!$E$2)-(Models!D30*weather!B24)-(Models!E30*weather!C24)-(Models!F30*weather!D24)-(Models!G30*weather!E24)-(Models!H30*weather!F24) -> 1.62713
B10: june | C10: =LOG($D$2)-(weather!B25*Models!D10)-(weather!C25*Models!E10)-(weather!D25*Models!F10)-(weather!E25*Models!G10)-(weather!F25*Models!H10) -> 1.653378 | E10: june | F10: =LOG($D$2)-(Models!D31*weather!B25)-(Models!E31*weather!C25)-(Models!F31*weather!D25)-(Models!G31*weather!E25)-(Models!H31*weather!F25) -> 1.618228 | H10: june | I10: =LOG(analysis!$E$2)-(Models!D31*weather!B25)-(Models!E31*weather!C25)-(Models!F31*weather!D25)-(Models!G31*weather!E25)-(Models!H31*weather!F25) -> 1.4721
B11: july | C11: =LOG($D$2)-(weather!B26*Models!D11)-(weather!C26*Models!E11)-(weather!D26*Models!F11)-(weather!E26*Models!G11)-(weather!F26*Models!H11) -> 1.550098 | E11: july | F11: =LOG($D$2)-(Models!D32*weather!B26)-(Models!E32*weather!C26)-(Models!F32*weather!D26)-(Models!G32*weather!E26)-(Models!H32*weather!F26) -> 1.530958 | H11: july | I11: =LOG(analysis!$E$2)-(Models!D32*weather!B26)-(Models!E32*weather!C26)-(Models!F32*weather!D26)-(Models!G32*weather!E26)-(Models!H32*weather!F26) -> 1.38483
B12: august | C12: =LOG($D$2)-(weather!B27*Models!D12)-(weather!C27*Models!E12)-(weather!D27*Models!F12)-(weather!E27*Models!G12)-(weather!F27*Models!H12) -> 1.635058 | E12: august | F12: =LOG($D$2)-(Models!D33*weather!B27)-(Models!E33*weather!C27)-(Models!F33*weather!D27)-(Models!G33*weather!E27)-(Models!H33*weather!F27) -> 1.603108 | H12: august | I12: =LOG(analysis!$E$2)-(Models!D33*weather!B27)-(Models!E33*weather!C27)-(Models!F33*weather!D27)-(Models!G33*weather!E27)-(Models!H33*weather!F27) -> 1.45698
B13: september | C13: =LOG($D$2)-(weather!B28*Models!D13)-(weather!C28*Models!E13)-(weather!D28*Models!F13)-(weather!E28*Models!G13)-(weather!F28*Models!H13) -> 1.748188 | E13: september | F13: =LOG($D$2)-(Models!D34*weather!B28)-(Models!E34*weather!C28)-(Models!F34*weather!D28)-(Models!G34*weather!E28)-(Models!H34*weather!F28) -> 1.748188 | H13: september | I13: =LOG(analysis!$E$2)-(Models!D34*weather!B28)-(Models!E34*weather!C28)-(Models!F34*weather!D28)-(Models!G34*weather!E28)-(Models!H34*weather!F28) -> 1.60206
B14: october | C14: =LOG($D$2)-(weather!B29*Models!D14)-(weather!C29*Models!E14)-(weather!D29*Models!F14)-(weather!E29*Models!G14)-(weather!F29*Models!H14) -> 1.736798 | E14: october | F14: =LOG($D$2)-(Models!D35*weather!B29)-(Models!E35*weather!C29)-(Models!F35*weather!D29)-(Models!G35*weather!E29)-(Models!H35*weather!F29) -> 1.783688 | H14: october | I14: =LOG(analysis!$E$2)-(Models!D35*weather!B29)-(Models!E35*weather!C29)-(Models!F35*weather!D29)-(Models!G35*weather!E29)-(Models!H35*weather!F29) -> 1.63756
B15: november | C15: =LOG($D$2)-(weather!B30*Models!D15)-(weather!C30*Models!E15)-(weather!D30*Models!F15)-(weather!E30*Models!G15)-(weather!F30*Models!H15) -> 1.920278 | E15: november | F15: =LOG($D$2)-(Models!D36*weather!B30)-(Models!E36*weather!C30)-(Models!F36*weather!D30)-(Models!G36*weather!E30)-(Models!H36*weather!F30) -> 2.122608 | H15: november | I15: =LOG(analysis!$E$2)-(Models!D36*weather!B30)-(Models!E36*weather!C30)-(Models!F36*weather!D30)-(Models!G36*weather!E30)-(Models!H36*weather!F30) -> 1.97648
B16: december | C16: =LOG($D$2)-(weather!B31*Models!D16)-(weather!C31*Models!E16)-(weather!D31*Models!F16)-(weather!E31*Models!G16)-(weather!F31*Models!H16) -> 2.151268 | E16: december | F16: =LOG($D$2)-(Models!D37*weather!B31)-(Models!E37*weather!C31)-(Models!F37*weather!D31)-(Models!G37*weather!E31)-(Models!H37*weather!F31) -> 2.140788 | H16: december | I16: =LOG(analysis!$E$2)-(Models!D37*weather!B31)-(Models!E37*weather!C31)-(Models!F37*weather!D31)-(Models!G37*weather!E31)-(Models!H37*weather!F31) -> 1.99466
C19: weekday | E19: weekend | H19: weekday ut | I19: weekday com
B20: September | C20: =IF(F2>0.11,H20,I20) -> 1.783688 | E20: =IF(B2="January",I5,IF(B2="february",I6,IF(B2="march",I7,IF(B2="april",I8,IF(B2="may",I9,IF(B2="june",I10,IF(B2="july",I11,IF(B2="august",I12,IF(B2="september",I13,IF(B2="october",I14,IF(B2="november",I15,IF(B2="december",I16,0)))))))))))) -> 1.63756 | H20: =IF(B2="January",F5,IF(B2="february",F6,IF(B2="march",F7,IF(B2="april",F8,IF(B2="may",F9,IF(B2="june",F10,IF(B2="july",F11,IF(B2="august",F12,IF(B2="september",F13,IF(B2="october",F14,IF(B2="november",F15,IF(B2="december",F16,0)))))))))))) -> 1.783688 | I20: =IF(B2="January",C5,IF(B2="february",C6,IF(B2="march",C7,IF(B2="april",C8,IF(B2="may",C9,IF(B2="june",C10,IF(B2="july",C11,IF(B2="august",C12,IF(B2="september",C13,IF(B2="october",C14,IF(B2="november",C15,IF(B2="december",C16,0)))))))))))) -> 1.736798
C26: weekday | E26: weekend | H26: weekday ut | I26: weekday com
B27: january | C27: =IF($J$2="Commuter model",I27,IF($J$2="Utilitrian model",H27,IF($J$2="Automatic model selection",IF($F$2>0.11,H27,I27)))) -> 21.604689 | E27: =10^($E$20+(Models!D26*weather!B20)+(Models!E26*weather!C20)+(Models!F26*weather!D20)+(Models!G26*weather!E20)+(Models!H25*weather!F20)) -> 15.431921 | H27: =10^($H$20+(Models!D26*weather!B20)+(Models!E26*weather!C20)+(Models!F26*weather!D20)+(Models!G26*weather!E20)+(Models!H25*weather!F20)) -> 21.604689 | I27: =10^($I$20+(weather!B20*Models!D5)+(weather!C20*Models!E5)+(weather!D20*Models!F5)+(weather!E20*Models!G5)+(weather!F20*Models!H5)) -> 11.719202
B28: february | C28: =IF($J$2="Commuter model",I28,IF($J$2="Utilitrian model",H28,IF($J$2="Automatic model selection",IF($F$2>0.11,H28,I28)))) -> 19.924986 | E28: =10^($E$20+(Models!D27*weather!B21)+(Models!E27*weather!C21)+(Models!F27*weather!D21)+(Models!G27*weather!E21)+(Models!H26*weather!F21)) -> 14.232133 | H28: =10^($H$20+(Models!D27*weather!B21)+(Models!E27*weather!C21)+(Models!F27*weather!D21)+(Models!G27*weather!E21)+(Models!H26*weather!F21)) -> 19.924986 | I28: =10^($I$20+(weather!B21*Models!D6)+(weather!C21*Models!E6)+(weather!D21*Models!F6)+(weather!E21*Models!G6)+(weather!F21*Models!H6)) -> 30.220248
B29: march | C29: =IF($J$2="Commuter model",I29,IF($J$2="Utilitrian model",H29,IF($J$2="Automatic model selection",IF($F$2>0.11,H29,I29)))) -> 40.787588 | E29: =10^($E$20+(Models!D28*weather!B22)+(Models!E28*weather!C22)+(Models!F28*weather!D22)+(Models!G28*weather!E22)+(Models!H27*weather!F22)) -> 29.133992 | H29: =10^($H$20+(Models!D28*weather!B22)+(Models!E28*weather!C22)+(Models!F28*weather!D22)+(Models!G28*weather!E22)+(Models!H27*weather!F22)) -> 40.787588 | I29: =10^($I$20+(weather!B22*Models!D7)+(weather!C22*Models!E7)+(weather!D22*Models!F7)+(weather!E22*Models!G7)+(weather!F22*Models!H7)) -> 44.55311
B30: april | C30: =IF($J$2="Commuter model",I30,IF($J$2="Utilitrian model",H30,IF($J$2="Automatic model selection",IF($F$2>0.11,H30,I30)))) -> 40.744409 | E30: =10^($E$20+(Models!D29*weather!B23)+(Models!E29*weather!C23)+(Models!F29*weather!D23)+(Models!G29*weather!E23)+(Models!H28*weather!F23)) -> 29.10315 | H30: =10^($H$20+(Models!D29*weather!B23)+(Models!E29*weather!C23)+(Models!F29*weather!D23)+(Models!G29*weather!E23)+(Models!H28*weather!F23)) -> 40.744409 | I30: =10^($I$20+(weather!B23*Models!D8)+(weather!C23*Models!E8)+(weather!D23*Models!F8)+(weather!E23*Models!G8)+(weather!F23*Models!H8)) -> 43.06238
B31: may | C31: =IF($J$2="Commuter model",I31,IF($J$2="Utilitrian model",H31,IF($J$2="Automatic model selection",IF($F$2>0.11,H31,I31)))) -> 57.361173 | E31: =10^($E$20+(Models!D30*weather!B24)+(Models!E30*weather!C24)+(Models!F30*weather!D24)+(Models!G30*weather!E24)+(Models!H29*weather!F24)) -> 40.972267 | H31: =10^($H$20+(Models!D30*weather!B24)+(Models!E30*weather!C24)+(Models!F30*weather!D24)+(Models!G30*weather!E24)+(Models!H29*weather!F24)) -> 57.361173 | I31: =10^($I$20+(weather!B24*Models!D9)+(weather!C24*Models!E9)+(weather!D24*Models!F9)+(weather!E24*Models!G9)+(weather!F24*Models!H9)) -> 55.509591
B32: june | C32: =IF($J$2="Commuter model",I32,IF($J$2="Utilitrian model",H32,IF($J$2="Automatic model selection",IF($F$2>0.11,H32,I32)))) -> 81.968696 | E32: =10^($E$20+(Models!D31*weather!B25)+(Models!E31*weather!C25)+(Models!F31*weather!D25)+(Models!G31*weather!E25)+(Models!H30*weather!F25)) -> 58.549069 | H32: =10^($H$20+(Models!D31*weather!B25)+(Models!E31*weather!C25)+(Models!F31*weather!D25)+(Models!G31*weather!E25)+(Models!H30*weather!F25)) -> 81.968696 | I32: =10^($I$20+(weather!B25*Models!D10)+(weather!C25*Models!E10)+(weather!D25*Models!F10)+(weather!E25*Models!G10)+(weather!F25*Models!H10)) -> 67.859089
B33: july | C33: =IF($J$2="Commuter model",I33,IF($J$2="Utilitrian model",H33,IF($J$2="Automatic model selection",IF($F$2>0.11,H33,I33)))) -> 100.21161 | E33: =10^($E$20+(Models!D32*weather!B26)+(Models!E32*weather!C26)+(Models!F32*weather!D26)+(Models!G32*weather!E26)+(Models!H31*weather!F26)) -> 71.579719 | H33: =10^($H$20+(Models!D32*weather!B26)+(Models!E32*weather!C26)+(Models!F32*weather!D26)+(Models!G32*weather!E26)+(Models!H31*weather!F26)) -> 100.21161 | I33: =10^($I$20+(weather!B26*Models!D11)+(weather!C26*Models!E11)+(weather!D26*Models!F11)+(weather!E26*Models!G11)+(weather!F26*Models!H11)) -> 86.077179
B34: august | C34: =IF($J$2="Commuter model",I34,IF($J$2="Utilitrian model",H34,IF($J$2="Automatic model selection",IF($F$2>0.11,H34,I34)))) -> 84.872702 | E34: =10^($E$20+(Models!D33*weather!B27)+(Models!E33*weather!C27)+(Models!F33*weather!D27)+(Models!G33*weather!E27)+(Models!H32*weather!F27)) -> 60.623358 | H34: =10^($H$20+(Models!D33*weather!B27)+(Models!E33*weather!C27)+(Models!F33*weather!D27)+(Models!G33*weather!E27)+(Models!H32*weather!F27)) -> 84.872702 | I34: =10^($I$20+(weather!B27*Models!D12)+(weather!C27*Models!E12)+(weather!D27*Models!F12)+(weather!E27*Models!G12)+(weather!F27*Models!H12)) -> 70.782847
B35: september | C35: =IF($J$2="Commuter model",I35,IF($J$2="Utilitrian model",H35,IF($J$2="Automatic model selection",IF($F$2>0.11,H35,I35)))) -> 60.769831 | E35: =10^($E$20+(Models!D34*weather!B28)+(Models!E34*weather!C28)+(Models!F34*weather!D28)+(Models!G34*weather!E28)+(Models!H33*weather!F28)) -> 43.407022 | H35: =10^($H$20+(Models!D34*weather!B28)+(Models!E34*weather!C28)+(Models!F34*weather!D28)+(Models!G34*weather!E28)+(Models!H33*weather!F28)) -> 60.769831 | I35: =10^($I$20+(weather!B28*Models!D13)+(weather!C28*Models!E13)+(weather!D28*Models!F13)+(weather!E28*Models!G13)+(weather!F28*Models!H13)) -> 54.550411
B36: october | C36: =IF($J$2="Commuter model",I36,IF($J$2="Utilitrian model",H36,IF($J$2="Automatic model selection",IF($F$2>0.11,H36,I36)))) -> 56 | E36: =10^($E$20+(Models!D35*weather!B29)+(Models!E35*weather!C29)+(Models!F35*weather!D29)+(Models!G35*weather!E29)+(Models!H34*weather!F29)) -> 40 | H36: =10^($H$20+(Models!D35*weather!B29)+(Models!E35*weather!C29)+(Models!F35*weather!D29)+(Models!G35*weather!E29)+(Models!H34*weather!F29)) -> 56 | I36: =10^($I$20+(weather!B29*Models!D14)+(weather!C29*Models!E14)+(weather!D29*Models!F14)+(weather!E29*Models!G14)+(weather!F29*Models!H14)) -> 56
B37: november | C37: =IF($J$2="Commuter model",I37,IF($J$2="Utilitrian model",H37,IF($J$2="Automatic model selection",IF($F$2>0.11,H37,I37)))) -> 25.660672 | E37: =10^($E$20+(Models!D36*weather!B30)+(Models!E36*weather!C30)+(Models!F36*weather!D30)+(Models!G36*weather!E30)+(Models!H35*weather!F30)) -> 18.329051 | H37: =10^($H$20+(Models!D36*weather!B30)+(Models!E36*weather!C30)+(Models!F36*weather!D30)+(Models!G36*weather!E30)+(Models!H35*weather!F30)) -> 25.660672 | I37: =10^($I$20+(weather!B30*Models!D15)+(weather!C30*Models!E15)+(weather!D30*Models!F15)+(weather!E30*Models!G15)+(weather!F30*Models!H15)) -> 36.703546
B38: december | C38: =IF($J$2="Commuter model",I38,IF($J$2="Utilitrian model",H38,IF($J$2="Automatic model selection",IF($F$2>0.11,H38,I38)))) -> 24.608663 | E38: =10^($E$20+(Models!D37*weather!B31)+(Models!E37*weather!C31)+(Models!F37*weather!D31)+(Models!G37*weather!E31)+(Models!H36*weather!F31)) -> 17.577617 | H38: =10^($H$20+(Models!D37*weather!B31)+(Models!E37*weather!C31)+(Models!F37*weather!D31)+(Models!G37*weather!E31)+(Models!H36*weather!F31)) -> 24.608663 | I38: =10^($I$20+(weather!B31*Models!D16)+(weather!C31*Models!E16)+(weather!D31*Models!F16)+(weather!E31*Models!G16)+(weather!F31*Models!H16)) -> 21.563439
C43: weekday | D43: weekend | I43: Months | J43: Usage (cyclists) | L43: TRUE
B44: =B27 -> january | C44: =C27 -> 21.604689 | D44: =E27 -> 15.431921 | I44: January | J44: =IF($L$43=TRUE,C44+D44,0) -> 37.03661
B45: =B28 -> february | C45: =C28 -> 19.924986 | D45: =E28 -> 14.232133 | I45: February | J45: =IF($L$43=TRUE,C45+D45,0) -> 34.157119
B46: =B29 -> march | C46: =C29 -> 40.787588 | D46: =E29 -> 29.133992 | I46: March | J46: =IF($L$43=TRUE,C46+D46,0) -> 69.92158
B47: =B30 -> april | C47: =C30 -> 40.744409 | D47: =E30 -> 29.10315 | I47: April | J47: =IF($L$43=TRUE,C47+D47,0) -> 69.847559
B48: =B31 -> may | C48: =C31 -> 57.361173 | D48: =E31 -> 40.972267 | I48: May | J48: =IF($L$43=TRUE,C48+D48,0) -> 98.33344
B49: =B32 -> june | C49: =C32 -> 81.968696 | D49: =E32 -> 58.549069 | I49: June | J49: =IF($L$43=TRUE,C49+D49,0) -> 140.51776
B50: =B33 -> july | C50: =C33 -> 100.21161 | D50: =E33 -> 71.579719 | I50: July | J50: =IF($L$43=TRUE,C50+D50,0) -> 171.79133
B51: =B34 -> august | C51: =C34 -> 84.872702 | D51: =E34 -> 60.623358 | I51: August | J51: =IF($L$43=TRUE,C51+D51,0) -> 145.49606
B52: =B35 -> september | C52: =C35 -> 60.769831 | D52: =E35 -> 43.407022 | I52: September | J52: =IF($L$43=TRUE,C52+D52,0) -> 104.17685
...

Sheet Models
A3: commuter model | D3: Mean Temp (°C) | E3: Total Precip (mm) | F3: Snow on Grnd (cm) | G3: average wind speed | H3: sunlight hours
C4: Reference month
C5: January | D5: 0.021 | E5: -0.019 | G5: -0.003 | H5: 0.097
C6: February | D6: 0.02 | E6: -0.029 | G6: -0.005
C7: March | D7: 0.017 | E7: -0.032 | F7: -0.008 | G7: -0.006
C8: April | D8: 0.025 | E8: -0.017 | G8: -0.009
C9: May | D9: 0.02 | E9: -0.033 | G9: -0.006
C10: June | D10: 0.018 | E10: -0.011 | G10: -0.005
C11: July | D11: 0.027 | E11: -0.009 | G11: -0.006
C12: August | D12: 0.022 | E12: -0.013 | G12: -0.007
C13: September
C14: October | D14: 0.015 | E14: -0.026 | F14: -0.052 | G14: -0.003
C15: November | D15: 0.014 | E15: -0.017 | F15: -0.021 | G15: -0.006
C16: December | D16: 0.017 | E16: -0.018 | F16: -0.035 | G16: -0.004
A24: Utilitrian model | D24: Mean Temp (°C) | E24: Total Precip (mm) | F24: Snow on Grnd (cm) | G24: average wind speed
C26: January | D26: 0.034 | E26: -0.023 | G26: -0.006
C27: February | D27: 0.032 | E27: -0.014 | G27: -0.015
C28: March | D28: 0.032 | E28: -0.046 | F28: -0.016
C29: April | D29: 0.04 | E29: -0.015 | G29: -0.009
C30: May | D30: 0.03 | E30: -0.023 | G30: -0.012
C31: June | D31: 0.023 | E31: -0.033
C32: July | D32: 0.027 | E32: -0.028
C33: August | D33: 0.028 | E33: -0.016 | G33: -0.01
C34: September
C35: October | D35: 0.025 | E35: -0.015 | F35: -0.092
C36: November | D36: 0.039 | E36: -0.044
C37: December | D37: 0.023 | E37: -0.023 | F37: -0.017 | G37: -0.012
A41: Weather data
A42: Enter your weather data
A43: Calgary weather (2013)
A44: Calgary weather (2014)
A45: Calgary weather (2015)
A46: Calgary weather (2016)
A47: Calgary weather (2017)

Sheet weather
I1: selected year
B2: Mean Temp (°C) | C2: Total Precip (mm) | D2: Snow on Grnd (cm) | E2: average wind speed | F2: sunlight hours | I2: ='Cycling usage estimation'!F9 -> Calgary weather (2015)
A3: January | B3: =IF($I$2="Calgary weather (2013)",M7,IF($I$2="Calgary weather (2014)",M24,IF($I$2="Calgary weather (2015)",M40,IF($I$2="Calgary weather (2016)",M56,IF($I$2="Calgary weather (2017)",M72,IF($I$2="Enter your weather data",M90,0)))))) -> -2.97 | C3: =IF($I$2="Calgary weather (2013)",N7,IF($I$2="Calgary weather (2014)",N24,IF($I$2="Calgary weather (2015)",N40,IF($I$2="Calgary weather (2016)",N56,IF($I$2="Calgary weather (2017)",N72,IF($I$2="Enter your weather data",N90,0)))))) -> 1.05 | D3: =IF($I$2="Calgary weather (2013)",O7,IF($I$2="Calgary weather (2014)",O24,IF($I$2="Calgary weather (2015)",O40,IF($I$2="Calgary weather (2016)",O56,IF($I$2="Calgary weather (2017)",O72,IF($I$2="Enter your weather data",O90,0)))))) -> 8.12 | E3: =IF($I$2="Calgary weather (2013)",P7,IF($I$2="Calgary weather (2014)",P24,IF($I$2="Calgary weather (2015)",P40,IF($I$2="Calgary weather (2016)",P56,IF($I$2="Calgary weather (2017)",P72,IF($I$2="Enter your weather data",P90,0)))))) -> 14.88 | F3: =IF($I$2="Calgary weather (2013)",Q7,IF($I$2="Calgary weather (2014)",Q24,IF($I$2="Calgary weather (2015)",Q40,IF($I$2="Calgary weather (2016)",Q56,IF($I$2="Calgary weather (2017)",Q72,IF($I$2="Enter your weather data",Q90,0)))))) -> 8.48
A4: February | B4: =IF($I$2="Calgary weather (2013)",M8,IF($I$2="Calgary weather (2014)",M25,IF($I$2="Calgary weather (2015)",M41,IF($I$2="Calgary weather (2016)",M57,IF($I$2="Calgary weather (2017)",M73,IF($I$2="Enter your weather data",M91,0)))))) -> -4.62 | C4: =IF($I$2="Calgary weather (2013)",N8,IF($I$2="Calgary weather (2014)",N25,IF($I$2="Calgary weather (2015)",N41,IF($I$2="Calgary weather (2016)",N57,IF($I$2="Calgary weather (2017)",N73,IF($I$2="Enter your weather data",N91,0)))))) -> 0.28 | D4: =IF($I$2="Calgary weather (2013)",O8,IF($I$2="Calgary weather (2014)",O25,IF($I$2="Calgary weather (2015)",O41,IF($I$2="Calgary weather (2016)",O57,IF($I$2="Calgary weather (2017)",O73,IF($I$2="Enter your weather data",O91,0)))))) -> 2.82 | E4: =IF($I$2="Calgary weather (2013)",P8,IF($I$2="Calgary weather (2014)",P25,IF($I$2="Calgary weather (2015)",P41,IF($I$2="Calgary weather (2016)",P57,IF($I$2="Calgary weather (2017)",P73,IF($I$2="Enter your weather data",P91,0)))))) -> 14.21 | F4: =IF($I$2="Calgary weather (2013)",Q8,IF($I$2="Calgary weather (2014)",Q25,IF($I$2="Calgary weather (2015)",Q41,IF($I$2="Calgary weather (2016)",Q57,IF($I$2="Calgary weather (2017)",Q73,IF($I$2="Enter your weather data",Q91,0)))))) -> 10
A5: March | B5: =IF($I$2="Calgary weather (2013)",M9,IF($I$2="Calgary weather (2014)",M26,IF($I$2="Calgary weather (2015)",M42,IF($I$2="Calgary weather (2016)",M58,IF($I$2="Calgary weather (2017)",M74,IF($I$2="Enter your weather data",M92,0)))))) -> 2.95 | C5: =IF($I$2="Calgary weather (2013)",N9,IF($I$2="Calgary weather (2014)",N26,IF($I$2="Calgary weather (2015)",N42,IF($I$2="Calgary weather (2016)",N58,IF($I$2="Calgary weather (2017)",N74,IF($I$2="Enter your weather data",N92,0)))))) -> 0.21 | D5: =IF($I$2="Calgary weather (2013)",O9,IF($I$2="Calgary weather (2014)",O26,IF($I$2="Calgary weather (2015)",O42,IF($I$2="Calgary weather (2016)",O58,IF($I$2="Calgary weather (2017)",O74,IF($I$2="Enter your weather data",O92,0)))))) -> 1.23 | E5: =IF($I$2="Calgary weather (2013)",P9,IF($I$2="Calgary weather (2014)",P26,IF($I$2="Calgary weather (2015)",P42,IF($I$2="Calgary weather (2016)",P58,IF($I$2="Calgary weather (2017)",P74,IF($I$2="Enter your weather data",P92,0)))))) -> 14.65 | F5: =IF($I$2="Calgary weather (2013)",Q9,IF($I$2="Calgary weather (2014)",Q26,IF($I$2="Calgary weather (2015)",Q42,IF($I$2="Calgary weather (2016)",Q58,IF($I$2="Calgary weather (2017)",Q74,IF($I$2="Enter your weather data",Q92,0)))))) -> 11.87 | M5: 2013
A6: April | B6: =IF($I$2="Calgary weather (2013)",M10,IF($I$2="Calgary weather (2014)",M27,IF($I$2="Calgary weather (2015)",M43,IF($I$2="Calgary weather (2016)",M59,IF($I$2="Calgary weather (2017)",M75,IF($I$2="Enter your weather data",M93,0)))))) -> 6.17 | C6: =IF($I$2="Calgary weather (2013)",N10,IF($I$2="Calgary weather (2014)",N27,IF($I$2="Calgary weather (2015)",N43,IF($I$2="Calgary weather (2016)",N59,IF($I$2="Calgary weather (2017)",N75,IF($I$2="Enter your weather data",N93,0)))))) -> 0.37 | D6: =IF($I$2="Calgary weather (2013)",O10,IF($I$2="Calgary weather (2014)",O27,IF($I$2="Calgary weather (2015)",O43,IF($I$2="Calgary weather (2016)",O59,IF($I$2="Calgary weather (2017)",O75,IF($I$2="Enter your weather data",O93,0)))))) -> 0.28 | E6: =IF($I$2="Calgary weather (2013)",P10,IF($I$2="Calgary weather (2014)",P27,IF($I$2="Calgary weather (2015)",P43,IF($I$2="Calgary weather (2016)",P59,IF($I$2="Calgary weather (2017)",P75,IF($I$2="Enter your weather data",P93,0)))))) -> 15.16 | F6: =IF($I$2="Calgary weather (2013)",Q10,IF($I$2="Calgary weather (2014)",Q27,IF($I$2="Calgary weather (2015)",Q43,IF($I$2="Calgary weather (2016)",Q59,IF($I$2="Calgary weather (2017)",Q75,IF($I$2="Enter your weather data",Q93,0)))))) -> 13.82 | M6: Mean Temp (°C) | N6: Total Precip (mm) | O6: Snow on Grnd (cm) | P6: average wind speed | Q6: sunlight hours
A7: May | B7: =IF($I$2="Calgary weather (2013)",M11,IF($I$2="Calgary weather (2014)",M28,IF($I$2="Calgary weather (2015)",M44,IF($I$2="Calgary weather (2016)",M60,IF($I$2="Calgary weather (2017)",M76,IF($I$2="Enter your weather data",M94,0)))))) -> 10.07 | C7: =IF($I$2="Calgary weather (2013)",N11,IF($I$2="Calgary weather (2014)",N28,IF($I$2="Calgary weather (2015)",N44,IF($I$2="Calgary weather (2016)",N60,IF($I$2="Calgary weather (2017)",N76,IF($I$2="Enter your weather data",N94,0)))))) -> 1.16 | D7: =IF($I$2="Calgary weather (2013)",O11,IF($I$2="Calgary weather (2014)",O28,IF($I$2="Calgary weather (2015)",O44,IF($I$2="Calgary weather (2016)",O60,IF($I$2="Calgary weather (2017)",O76,IF($I$2="Enter your weather data",O94,0)))))) -> 0 | E7: =IF($I$2="Calgary weather (2013)",P11,IF($I$2="Calgary weather (2014)",P28,IF($I$2="Calgary weather (2015)",P44,IF($I$2="Calgary weather (2016)",P60,IF($I$2="Calgary weather (2017)",P76,IF($I$2="Enter your weather data",P94,0)))))) -> 15.37 | F7: =IF($I$2="Calgary weather (2013)",Q11,IF($I$2="Calgary weather (2014)",Q28,IF($I$2="Calgary weather (2015)",Q44,IF($I$2="Calgary weather (2016)",Q60,IF($I$2="Calgary weather (2017)",Q76,IF($I$2="Enter your weather data",Q94,0)))))) -> 15.52 | L7: January | M7: -4.89 | N7: 0.24 | O7: 4.47 | P7: 17.41 | Q7: 8.48
A8: June | B8: =IF($I$2="Calgary weather (2013)",M12,IF($I$2="Calgary weather (2014)",M29,IF($I$2="Calgary weather (2015)",M45,IF($I$2="Calgary weather (2016)",M61,IF($I$2="Calgary weather (2017)",M77,IF($I$2="Enter your weather data",M95,0)))))) -> 15.87 | C8: =IF($I$2="Calgary weather (2013)",N12,IF($I$2="Calgary weather (2014)",N29,IF($I$2="Calgary weather (2015)",N45,IF($I$2="Calgary weather (2016)",N61,IF($I$2="Calgary weather (2017)",N77,IF($I$2="Enter your weather data",N95,0)))))) -> 1.93 | D8: =IF($I$2="Calgary weather (2013)",O12,IF($I$2="Calgary weather (2014)",O29,IF($I$2="Calgary weather (2015)",O45,IF($I$2="Calgary weather (2016)",O61,IF($I$2="Calgary weather (2017)",O77,IF($I$2="Enter your weather data",O95,0)))))) -> 0 | E8: =IF($I$2="Calgary weather (2013)",P12,IF($I$2="Calgary weather (2014)",P29,IF($I$2="Calgary weather (2015)",P45,IF($I$2="Calgary weather (2016)",P61,IF($I$2="Calgary weather (2017)",P77,IF($I$2="Enter your weather data",P95,0)))))) -> 13.17 | F8: =IF($I$2="Calgary weather (2013)",Q12,IF($I$2="Calgary weather (2014)",Q29,IF($I$2="Calgary weather (2015)",Q45,IF($I$2="Calgary weather (2016)",Q61,IF($I$2="Calgary weather (2017)",Q77,IF($I$2="Enter your weather data",Q95,0)))))) -> 16.42 | L8: February | M8: -1.45 | N8: 0.24 | O8: 2 | P8: 17.06 | Q8: 10
A9: July | B9: =IF($I$2="Calgary weather (2013)",M13,IF($I$2="Calgary weather (2014)",M30,IF($I$2="Calgary weather (2015)",M46,IF($I$2="Calgary weather (2016)",M62,IF($I$2="Calgary weather (2017)",M78,IF($I$2="Enter your weather data",M96,0)))))) -> 18.26 | C9: =IF($I$2="Calgary weather (2013)",N13,IF($I$2="Calgary weather (2014)",N30,IF($I$2="Calgary weather (2015)",N46,IF($I$2="Calgary weather (2016)",N62,IF($I$2="Calgary weather (2017)",N78,IF($I$2="Enter your weather data",N96,0)))))) -> 1.81 | D9: =IF($I$2="Calgary weather (2013)",O13,IF($I$2="Calgary weather (2014)",O30,IF($I$2="Calgary weather (2015)",O46,IF($I$2="Calgary weather (2016)",O62,IF($I$2="Calgary weather (2017)",O78,IF($I$2="Enter your weather data",O96,0)))))) -> 0 | E9: =IF($I$2="Calgary weather (2013)",P13,IF($I$2="Calgary weather (2014)",P30,IF($I$2="Calgary weather (2015)",P46,IF($I$2="Calgary weather (2016)",P62,IF($I$2="Calgary weather (2017)",P78,IF($I$2="Enter your weather data",P96,0)))))) -> 14.54 | F9: =IF($I$2="Calgary weather (2013)",Q13,IF($I$2="Calgary weather (2014)",Q30,IF($I$2="Calgary weather (2015)",Q46,IF($I$2="Calgary weather (2016)",Q62,IF($I$2="Calgary weather (2017)",Q78,IF($I$2="Enter your weather data",Q96,0)))))) -> 15.97 | L9: March | M9: -5.43 | N9: 0.86 | O9: 5.31 | P9: 15.34 | Q9: 11.87
A10: August | B10: =IF($I$2="Calgary weather (2013)",M14,IF($I$2="Calgary weather (2014)",M31,IF($I$2="Calgary weather (2015)",M47,IF($I$2="Calgary weather (2016)",M63,IF($I$2="Calgary weather (2017)",M79,IF($I$2="Enter your weather data",M97,0)))))) -> 16.92 | C10: =IF($I$2="Calgary weather (2013)",N14,IF($I$2="Calgary weather (2014)",N31,IF($I$2="Calgary weather (2015)",N47,IF($I$2="Calgary weather (2016)",N63,IF($I$2="Calgary weather (2017)",N79,IF($I$2="Enter your weather data",N97,0)))))) -> 4.16 | D10: =IF($I$2="Calgary weather (2013)",O14,IF($I$2="Calgary weather (2014)",O31,IF($I$2="Calgary weather (2015)",O47,IF($I$2="Calgary weather (2016)",O63,IF($I$2="Calgary weather (2017)",O79,IF($I$2="Enter your weather data",O97,0)))))) -> 0 | E10: =IF($I$2="Calgary weather (2013)",P14,IF($I$2="Calgary weather (2014)",P31,IF($I$2="Calgary weather (2015)",P47,IF($I$2="Calgary weather (2016)",P63,IF($I$2="Calgary weather (2017)",P79,IF($I$2="Enter your weather data",P97,0)))))) -> 12.64 | F10: =IF($I$2="Calgary weather (2013)",Q14,IF($I$2="Calgary weather (2014)",Q31,IF($I$2="Calgary weather (2015)",Q47,IF($I$2="Calgary weather (2016)",Q63,IF($I$2="Calgary weather (2017)",Q79,IF($I$2="Enter your weather data",Q97,0)))))) -> 14.46 | L10: April | M10: 2.03 | N10: 0.52 | O10: 3.16 | P10: 18.75 | Q10: 13.82
A11: September | B11: =IF($I$2="Calgary weather (2013)",M15,IF($I$2="Calgary weather (2014)",M32,IF($I$2="Calgary weather (2015)",M48,IF($I$2="Calgary weather (2016)",M64,IF($I$2="Calgary weather (2017)",M80,IF($I$2="Enter your weather data",M98,0)))))) -> 10.65 | C11: =IF($I$2="Calgary weather (2013)",N15,IF($I$2="Calgary weather (2014)",N32,IF($I$2="Calgary weather (2015)",N48,IF($I$2="Calgary weather (2016)",N64,IF($I$2="Calgary weather (2017)",N80,IF($I$2="Enter your weather data",N98,0)))))) -> 2.23 | D11: =IF($I$2="Calgary weather (2013)",O15,IF($I$2="Calgary weather (2014)",O32,IF($I$2="Calgary weather (2015)",O48,IF($I$2="Calgary weather (2016)",O64,IF($I$2="Calgary weather (2017)",O80,IF($I$2="Enter your weather data",O98,0)))))) -> 0 | E11: =IF($I$2="Calgary weather (2013)",P15,IF($I$2="Calgary weather (2014)",P32,IF($I$2="Calgary weather (2015)",P48,IF($I$2="Calgary weather (2016)",P64,IF($I$2="Calgary weather (2017)",P80,IF($I$2="Enter your weather data",P98,0)))))) -> 12.68 | F11: =IF($I$2="Calgary weather (2013)",Q15,IF($I$2="Calgary weather (2014)",Q32,IF($I$2="Calgary weather (2015)",Q48,IF($I$2="Calgary weather (2016)",Q64,IF($I$2="Calgary weather (2017)",Q80,IF($I$2="Enter your weather data",Q98,0)))))) -> 12.58 | L11: May | M11: 12.07 | N11: 3.88 | O11: 0 | P11: 16.29 | Q11: 15.52
A12: October | B12: =IF($I$2="Calgary weather (2013)",M16,IF($I$2="Calgary weather (2014)",M33,IF($I$2="Calgary weather (2015)",M49,IF($I$2="Calgary weather (2016)",M65,IF($I$2="Calgary weather (2017)",M81,IF($I$2="Enter your weather data",M99,0)))))) -> 8 | C12: =IF($I$2="Calgary weather (2013)",N16,IF($I$2="Calgary weather (2014)",N33,IF($I$2="Calgary weather (2015)",N49,IF($I$2="Calgary weather (2016)",N65,IF($I$2="Calgary weather (2017)",N81,IF($I$2="Enter your weather data",N99,0)))))) -> 0.18 | D12: =IF($I$2="Calgary weather (2013)",O16,IF($I$2="Calgary weather (2014)",O33,IF($I$2="Calgary weather (2015)",O49,IF($I$2="Calgary weather (2016)",O65,IF($I$2="Calgary weather (2017)",O81,IF($I$2="Enter your weather data",O99,0)))))) -> 0 | E12: =IF($I$2="Calgary weather (2013)",P16,IF($I$2="Calgary weather (2014)",P33,IF($I$2="Calgary weather (2015)",P49,IF($I$2="Calgary weather (2016)",P65,IF($I$2="Calgary weather (2017)",P81,IF($I$2="Enter your weather data",P99,0)))))) -> 13.4 | F12: =IF($I$2="Calgary weather (2013)",Q16,IF($I$2="Calgary weather (2014)",Q33,IF($I$2="Calgary weather (2015)",Q49,IF($I$2="Calgary weather (2016)",Q65,IF($I$2="Calgary weather (2017)",Q81,IF($I$2="Enter your weather data",Q99,0)))))) -> 10.65 | L12: June | M12: 14.04 | N12: 5.23 | O12: 0 | P12: 15.97 | Q12: 16.42
A13: November | B13: =IF($I$2="Calgary weather (2013)",M17,IF($I$2="Calgary weather (2014)",M34,IF($I$2="Calgary weather (2015)",M50,IF($I$2="Calgary weather (2016)",M66,IF($I$2="Calgary weather (2017)",M82,IF($I$2="Enter your weather data",M100,0)))))) -> -0.97 | C13: =IF($I$2="Calgary weather (2013)",N17,IF($I$2="Calgary weather (2014)",N34,IF($I$2="Calgary weather (2015)",N50,IF($I$2="Calgary weather (2016)",N66,IF($I$2="Calgary weather (2017)",N82,IF($I$2="Enter your weather data",N100,0)))))) -> 0.44 | D13: =IF($I$2="Calgary weather (2013)",O17,IF($I$2="Calgary weather (2014)",O34,IF($I$2="Calgary weather (2015)",O50,IF($I$2="Calgary weather (2016)",O66,IF($I$2="Calgary weather (2017)",O82,IF($I$2="Enter your weather data",O100,0)))))) -> 1.84 | E13: =IF($I$2="Calgary weather (2013)",P17,IF($I$2="Calgary weather (2014)",P34,IF($I$2="Calgary weather (2015)",P50,IF($I$2="Calgary weather (2016)",P66,IF($I$2="Calgary weather (2017)",P82,IF($I$2="Enter your weather data",P100,0)))))) -> 12.88 | F13: =IF($I$2="Calgary weather (2013)",Q17,IF($I$2="Calgary weather (2014)",Q34,IF($I$2="Calgary weather (2015)",Q50,IF($I$2="Calgary weather (2016)",Q66,IF($I$2="Calgary weather (2017)",Q82,IF($I$2="Enter your weather data",Q100,0)))))) -> 8.91 | L13: July | M13: 16.52 | N13: 1.56 | O13: 0 | P13: 14.83 | Q13: 15.97
A14: December | B14: =IF($I$2="Calgary weather (2013)",M18,IF($I$2="Calgary weather (2014)",M35,IF($I$2="Calgary weather (2015)",M51,IF($I$2="Calgary weather (2016)",M67,IF($I$2="Calgary weather (2017)",M83,IF($I$2="Enter your weather data",M101,0)))))) -> -5.83 | C14: =IF($I$2="Calgary weather (2013)",N18,IF($I$2="Calgary weather (2014)",N35,IF($I$2="Calgary weather (2015)",N51,IF($I$2="Calgary weather (2016)",N67,IF($I$2="Calgary weather (2017)",N83,IF($I$2="Enter your weather data",N101,0)))))) -> 0.63 | D14: =IF($I$2="Calgary weather (2013)",O18,IF($I$2="Calgary weather (2014)",O35,IF($I$2="Calgary weather (2015)",O51,IF($I$2="Calgary weather (2016)",O67,IF($I$2="Calgary weather (2017)",O83,IF($I$2="Enter your weather data",O101,0)))))) -> 4.6 | E14: =IF($I$2="Calgary weather (2013)",P18,IF($I$2="Calgary weather (2014)",P35,IF($I$2="Calgary weather (2015)",P51,IF($I$2="Calgary weather (2016)",P67,IF($I$2="Calgary weather (2017)",P83,IF($I$2="Enter your weather data",P101,0)))))) -> 10.36 | F14: =IF($I$2="Calgary weather (2013)",Q18,IF($I$2="Calgary weather (2014)",Q35,IF($I$2="Calgary weather (2015)",Q51,IF($I$2="Calgary weather (2016)",Q67,IF($I$2="Calgary weather (2017)",Q83,IF($I$2="Enter your weather data",Q101,0)))))) -> 7.95 | L14: August | M14: 17.46 | N14: 0.88 | O14: 0 | P14: 13.72 | Q14: 14.46
L15: September | M15: 14.18 | N15: 1.86 | O15: 0 | P15: 15.98 | Q15: 12.58
L16: October | M16: 5.56 | N16: 0.83 | O16: 3.2 | P16: 14.68 | Q16: 10.65
L17: November | M17: -3.32 | N17: 0.41 | O17: 1.73 | P17: 14.86 | Q17: 8.91
L18: December | M18: -9.51 | N18: 1.23 | O18: 12.54 | P18: 17.32 | Q18: 7.95
B19: Mean Temp (°C) | C19: Total Precip (mm) | D19: Snow on Grnd (cm) | E19: average wind speed | F19: sunlight hours
A20: January | B20: =B3-$B$11 -> -13.62 | C20: =C3-$C$11 -> -1.18 | D20: =D3-$D$11 -> 8.12 | E20: =E3-$E$11 -> 2.2 | F20: =F3-$F$11 -> -4.1
A21: February | B21: =B4-$B$11 -> -15.27 | C21: =C4-$C$11 -> -1.95 | D21: =D4-$D$11 -> 2.82 | E21: =E4-$E$11 -> 1.53 | F21: =F4-$F$11 -> -2.58
A22: March | B22: =B5-$B$11 -> -7.7 | C22: =C5-$C$11 -> -2.02 | D22: =D5-$D$11 -> 1.23 | E22: =E5-$E$11 -> 1.97 | F22: =F5-$F$11 -> -0.71 | M22: 2014
A23: April | B23: =B6-$B$11 -> -4.48 | C23: =C6-$C$11 -> -1.86 | D23: =D6-$D$11 -> 0.28 | E23: =E6-$E$11 -> 2.48 | F23: =F6-$F$11 -> 1.24 | M23: Mean Temp (°C) | N23: Total Precip (mm) | O23: Snow on Grnd (cm) | P23: average wind speed | Q23: sunlight hours
A24: May | B24: =B7-$B$11 -> -0.58 | C24: =C7-$C$11 -> -1.07 | D24: =D7-$D$11 -> 0 | E24: =E7-$E$11 -> 2.69 | F24: =F7-$F$11 -> 2.94 | L24: January | M24: -3.09 | N24: 0.49 | O24: 4.4 | P24: 15.63 | Q24: 8.48
A25: June | B25: =B8-$B$11 -> 5.22 | C25: =C8-$C$11 -> -0.3 | D25: =D8-$D$11 -> 0 | E25: =E8-$E$11 -> 0.49 | F25: =F8-$F$11 -> 3.84 | L25: February | M25: -12.16 | N25: 0.15 | O25: 1.92 | P25: 14.46 | Q25: 10
A26: July | B26: =B9-$B$11 -> 7.61 | C26: =C9-$C$11 -> -0.42 | D26: =D9-$D$11 -> 0 | E26: =E9-$E$11 -> 1.86 | F26: =F9-$F$11 -> 3.39 | L26: March | M26: -6.7 | N26: 0.56 | O26: 2.22 | P26: 15.23 | Q26: 11.87
A27: August | B27: =B10-$B$11 -> 6.27 | C27: =C10-$C$11 -> 1.93 | D27: =D10-$D$11 -> 0 | E27: =E10-$E$11 -> -0.04 | F27: =F10-$F$11 -> 1.88 | L27: April | M27: 4.22 | N27: 0.77 | O27: 1.83 | P27: 16.05 | Q27: 13.82
A28: September | B28: =B11-$B$11 -> 0 | C28: =C11-$C$11 -> 0 | D28: =D11-$D$11 -> 0 | E28: =E11-$E$11 -> 0 | F28: =F11-$F$11 -> 0 | L28: May | M28: 9.27 | N28: 2.07 | O28: 0.71 | P28: 14.7 | Q28: 15.52
A29: October | B29: =B12-$B$11 -> -2.65 | C29: =C12-$C$11 -> -2.05 | D29: =D12-$D$11 -> 0 | E29: =E12-$E$11 -> 0.72 | F29: =F12-$F$11 -> -1.93 | L29: June | M29: 13.08 | N29: 2.85 | O29: 0 | P29: 16.23 | Q29: 16.42
A30: November | B30: =B13-$B$11 -> -11.62 | C30: =C13-$C$11 -> -1.79 | D30: =D13-$D$11 -> 1.84 | E30: =E13-$E$11 -> 0.2 | F30: =F13-$F$11 -> -3.67 | L30: July | M30: 18.66 | N30: 0.85 | O30: 0 | P30: 15.56 | Q30: 15.97
A31: December | B31: =B14-$B$11 -> -16.48 | C31: =C14-$C$11 -> -1.6 | D31: =D14-$D$11 -> 4.6 | E31: =E14-$E$11 -> -2.32 | F31: =F14-$F$11 -> -4.63 | L31: August | M31: 16.68 | N31: 1.68 | O31: 0 | P31: 12.1 | Q31: 14.46
L32: September | M32: 11.78 | N32: 1.82 | O32: 0 | P32: 13.18 | Q32: 12.58
L33: October | M33: 8.3 | N33: 0.21 | O33: 0 | P33: 13.1 | Q33: 10.65
L34: November | M34: -5.17 | N34: 1.44 | O34: 4.78 | P34: 14.14 | Q34: 8.91
L35: December | M35: -3.39 | N35: 0.15 | O35: 2.17 | P35: 11.51 | Q35: 7.97
M38: 2015
M39: Mean Temp (°C) | N39: Total Precip (mm) | O39: Snow on Grnd (cm) | P39: average wind speed | Q39: sunlight hours
L40: January | M40: -2.97 | N40: 1.05 | O40: 8.12 | P40: 14.88 | Q40: 8.48
L41: February | M41: -4.62 | N41: 0.28 | O41: 2.82 | P41: 14.21 | Q41: 10
L42: March | M42: 2.95 | N42: 0.21 | O42: 1.23 | P42: 14.65 | Q42: 11.87
...
